Workbook

Sheet Thông tin dự án
A1: DỮ LIỆU GIẢ LẬP — dự án tham chiếu cho bộ demo Tokai Minato (không phải dự án thật)
A3: Mã case study | B3: cs_rag_scan_manual_foundry_jp
A4: Tên dự án | B4: Tra cứu tài liệu kỹ thuật dạng scan cho nhà máy đúc (giả lập)
A5: Ngành | B5: Đúc kim loại
A6: Thị trường / ngôn ngữ khách | B6: jp / ja
A7: Hướng giải pháp | B7: rag
A8: Số requirement | B8: 24
A9: Hệ số áp dụng khi ước lượng | B9: customer_jp, ocr
A10: Công nghệ | B10: Azure OpenAI, Azure AI Search, Azure AI Document Intelligence, Python
A11: Tháng chào thầu | B11: 2025-01
A12: Kết quả chào thầu | B12: Trúng thầu
A13: Hợp đồng | B13: PoC: 準委任 · MVP: 請負 · Vận hành: 準委任
A14: Lý do | B14: Cam kết trả lời kèm ảnh trang gốc để kỹ sư tự kiểm chứng.
A15: Tóm tắt | B15: Hỏi đáp trên khoảng 25.000 trang tài liệu kỹ thuật cũ, khoảng 60% là bản scan có chữ viết tay và bảng biểu; trả lời kèm ảnh trang gốc.
A16: Loại WBS | B16: WBS ước lượng khi chào thầu và effort thực tế sau dự án

Sheet WBS
A1: Mã | B1: Hạng mục (VI) | C1: 作業項目 (JA) | D1: Giai đoạn | E1: Vai trò | F1: Man-day ước lượng | G1: Man-day thực tế | H1: Chênh lệch | I1: Requirement liên quan | J1: Ghi chú
A2: 1 | B2: PoC | C2: PoC | D2: PoC
A3: 1.1 | B3: Quản lý PoC | C3: PoC管理 | D3: PoC
A4: 1.1.01 | B4: Kickoff và lập kế hoạch PoC | C4: PoCキックオフ・計画策定 | D4: PoC | E4: PM | F4: 3 | G4: 3.5 | H4: =G4-F4
A5: 1.1.02 | B5: Họp định kỳ và báo cáo tuần | C5: 週次定例・報告 | D5: PoC | E5: PM | F5: 4.5 | G5: 5.5 | H5: =G5-F5
A6: 1.1.03 | B6: Cầu nối với khách, dịch tài liệu | C6: ブリッジSE・資料翻訳 | D6: PoC | E6: BrSE | F6: 5.5 | G6: 7 | H6: =G6-F6
A7: 1.2 | B7: Khảo sát và chuẩn bị dữ liệu | C7: データ調査・準備 | D7: PoC
A8: 1.2.01 | B8: Khảo sát tài liệu, phân loại text/scan | C8: 文書調査・テキスト/スキャン分類 | D8: PoC | E8: BA | F8: 4.5 | G8: 9.5 | H8: =G8-F8 | I8: R-DOC-02 | J8: Vượt ước lượng (xem bài học)
A9: 1.2.02 | B9: Chọn tập tài liệu PoC | C9: PoC対象文書の選定 | D9: PoC | E9: BA | F9: 2 | G9: 3 | H9: =G9-F9
A10: 1.3 | B10: Pipeline RAG thử nghiệm | C10: RAGパイプライン試作 | D10: PoC
A11: 1.3.01 | B11: OCR tài liệu scan | C11: スキャン文書のOCR処理 | D11: PoC | E11: AI Engineer | F11: 6 | G11: 12.5 | H11: =G11-F11 | I11: R-DOC-02 | J11: Vượt ước lượng (xem bài học)
A12: 1.3.02 | B12: Chia đoạn và tạo chỉ mục tìm kiếm | C12: チャンク分割・検索インデックス作成 | D12: PoC | E12: AI Engineer | F12: 5.5 | G12: 7 | H12: =G12-F12
A13: 1.3.03 | B13: Prompt trả lời kèm trích dẫn nguồn | C13: 根拠付き回答プロンプト設計 | D13: PoC | E13: AI Engineer | F13: 5.5 | G13: 7 | H13: =G13-F13
A14: 1.3.04 | B14: API backend PoC | C14: PoCバックエンドAPI | D14: PoC | E14: Backend | F14: 5.5 | G14: 7 | H14: =G14-F14
A15: 1.4 | B15: Giao diện và hạ tầng PoC | C15: 画面・基盤（PoC） | D15: PoC
A16: 1.4.01 | B16: Màn hình chat hiển thị nguồn | C16: 根拠表示付きチャット画面 | D16: PoC | E16: Frontend | F16: 5 | G16: 6 | H16: =G16-F16
A17: 1.4.02 | B17: Dựng môi trường cloud PoC | C17: PoC環境構築 | D17: PoC | E17: Infra | F17: 4.5 | G17: 5.5 | H17: =G17-F17
A18: 1.4.03 | B18: Đăng nhập một lần (SSO) | C18: シングルサインオン設定 | D18: PoC | E18: Infra | F18: 2 | G18: 2.5 | H18: =G18-F18
A19: 1.5 | B19: Đánh giá PoC | C19: PoC評価 | D19: PoC
A20: 1.5.01 | B20: Bộ câu hỏi đánh giá và đáp án | C20: 評価用質問・正解データ整備 | D20: PoC | E20: QA | F20: 4.5 | G20: 5.5 | H20: =G20-F20
A21: 1.5.02 | B21: Đo tỉ lệ trả lời đúng | C21: 正答率測定 | D21: PoC | E21: QA | F21: 4.5 | G21: 5.5 | H21: =G21-F21
A22: 1.5.03 | B22: Đánh giá tại hiện trường | C22: 現場評価（5段階） | D22: PoC | E22: QA | F22: 3 | G22: 3.5 | H22: =G22-F22
A23: 1.5.04 | B23: Báo cáo kết quả, đề xuất go/no-go | C23: PoC結果報告・本開発判断資料 | D23: PoC | E23: PM | F23: 4.5 | G23: 5.5 | H23: =G23-F23
A24: 2 | B24: MVP (本開発) | C24: 本開発 | D24: MVP
A25: 2.1 | B25: Quản lý dự án | C25: プロジェクト管理 | D25: MVP
A26: 2.1.01 | B26: Kế hoạch chi tiết | C26: 詳細計画 | D26: MVP | E26: PM | F26: 6.5 | G26: 7 | H26: =G26-F26
A27: 2.1.02 | B27: Họp tuần và báo cáo tháng (đợt 1/2) | C27: 定例・月次報告（1/2） | D27: MVP | E27: PM | F27: 6.5 | G27: 7 | H27: =G27-F27
A28: 2.1.03 | B28: Họp tuần và báo cáo tháng (đợt 2/2) | C28: 定例・月次報告（2/2） | D28: MVP | E28: PM | F28: 6.5 | G28: 7 | H28: =G28-F28
A29: 2.1.04 | B29: Quản lý rủi ro và thay đổi | C29: リスク・変更管理 | D29: MVP | E29: PM | F29: 8 | G29: 8.5 | H29: =G29-F29
A30: 2.1.05 | B30: BrSE giao tiếp với khách (đợt 1/2) | C30: ブリッジSE対応（1/2） | D30: MVP | E30: BrSE | F30: 6.5 | G30: 7 | H30: =G30-F30
A31: 2.1.06 | B31: BrSE giao tiếp với khách (đợt 2/2) | C31: ブリッジSE対応（2/2） | D31: MVP | E31: BrSE | F31: 6.5 | G31: 7 | H31: =G31-F31
A32: 2.2 | B32: Thiết kế | C32: 設計 | D32: MVP
A33: 2.2.01 | B33: Chi tiết hóa yêu cầu (đợt 1/2) | C33: 要件定義詳細化（1/2） | D33: MVP | E33: BA | F33: 6.5 | G33: 7 | H33: =G33-F33
A34: 2.2.02 | B34: Chi tiết hóa yêu cầu (đợt 2/2) | C34: 要件定義詳細化（2/2） | D34: MVP | E34: BA | F34: 6.5 | G34: 7 | H34: =G34-F34
A35: 2.2.03 | B35: Thiết kế kiến trúc cloud | C35: クラウドアーキテクチャ設計 | D35: MVP | E35: Infra | F35: 8 | G35: 8.5 | H35: =G35-F35
A36: 2.2.04 | B36: Thiết kế màn hình | C36: 画面設計 | D36: MVP | E36: Frontend | F36: 8 | G36: 8.5 | H36: =G36-F36
A37: 2.2.05 | B37: Thiết kế bảo mật và phân quyền | C37: セキュリティ・権限設計 | D37: MVP | E37: Backend | F37: 8 | G37: 8.5 | H37: =G37-F37
A38: 2.3 | B38: Dữ liệu và chỉ mục toàn bộ | C38: 全データ取込・インデックス | D38: MVP
A39: 2.3.01 | B39: OCR toàn bộ tài liệu scan (đợt 1/2) | C39: 全スキャン文書のOCR（1/2） | D39: MVP | E39: AI Engineer | F39: 6.5 | G39: 13.5 | H39: =G39-F39 | I39: R-DOC-02 | J39: Vượt ước lượng (xem bài học)
A40: 2.3.02 | B40: OCR toàn bộ tài liệu scan (đợt 2/2) | C40: 全スキャン文書のOCR（2/2） | D40: MVP | E40: AI Engineer | F40: 6.5 | G40: 13.5 | H40: =G40-F40 | I40: R-DOC-02 | J40: Vượt ước lượng (xem bài học)
...

Sheet Tổng hợp
A1: Giai đoạn | B1: Vai trò | C1: Man-day ước lượng | D1: Man-day thực tế | E1: Thực tế / ước lượng
A2: PoC | B2: PM | C2: =SUMIFS(WBS!F2:F94,WBS!D2:D94,A2,WBS!E2:E94,B2) | D2: =SUMIFS(WBS!G2:G94,WBS!D2:D94,A2,WBS!E2:E94,B2) | E2: =IF(C2=0,"",ROUND(D2/C2,2))
A3: PoC | B3: BA | C3: =SUMIFS(WBS!F2:F94,WBS!D2:D94,A3,WBS!E2:E94,B3) | D3: =SUMIFS(WBS!G2:G94,WBS!D2:D94,A3,WBS!E2:E94,B3) | E3: =IF(C3=0,"",ROUND(D3/C3,2))
A4: PoC | B4: BrSE | C4: =SUMIFS(WBS!F2:F94,WBS!D2:D94,A4,WBS!E2:E94,B4) | D4: =SUMIFS(WBS!G2:G94,WBS!D2:D94,A4,WBS!E2:E94,B4) | E4: =IF(C4=0,"",ROUND(D4/C4,2))
A5: PoC | B5: AI Engineer | C5: =SUMIFS(WBS!F2:F94,WBS!D2:D94,A5,WBS!E2:E94,B5) | D5: =SUMIFS(WBS!G2:G94,WBS!D2:D94,A5,WBS!E2:E94,B5) | E5: =IF(C5=0,"",ROUND(D5/C5,2))
A6: PoC | B6: Backend | C6: =SUMIFS(WBS!F2:F94,WBS!D2:D94,A6,WBS!E2:E94,B6) | D6: =SUMIFS(WBS!G2:G94,WBS!D2:D94,A6,WBS!E2:E94,B6) | E6: =IF(C6=0,"",ROUND(D6/C6,2))
A7: PoC | B7: Frontend | C7: =SUMIFS(WBS!F2:F94,WBS!D2:D94,A7,WBS!E2:E94,B7) | D7: =SUMIFS(WBS!G2:G94,WBS!D2:D94,A7,WBS!E2:E94,B7) | E7: =IF(C7=0,"",ROUND(D7/C7,2))
A8: PoC | B8: QA | C8: =SUMIFS(WBS!F2:F94,WBS!D2:D94,A8,WBS!E2:E94,B8) | D8: =SUMIFS(WBS!G2:G94,WBS!D2:D94,A8,WBS!E2:E94,B8) | E8: =IF(C8=0,"",ROUND(D8/C8,2))
A9: PoC | B9: Infra | C9: =SUMIFS(WBS!F2:F94,WBS!D2:D94,A9,WBS!E2:E94,B9) | D9: =SUMIFS(WBS!G2:G94,WBS!D2:D94,A9,WBS!E2:E94,B9) | E9: =IF(C9=0,"",ROUND(D9/C9,2))
A10: Tổng PoC | C10: =SUMIFS(WBS!F2:F94,WBS!D2:D94,"PoC") | D10: =SUMIFS(WBS!G2:G94,WBS!D2:D94,"PoC") | E10: =IF(C10=0,"",ROUND(D10/C10,2))
A11: MVP | B11: PM | C11: =SUMIFS(WBS!F2:F94,WBS!D2:D94,A11,WBS!E2:E94,B11) | D11: =SUMIFS(WBS!G2:G94,WBS!D2:D94,A11,WBS!E2:E94,B11) | E11: =IF(C11=0,"",ROUND(D11/C11,2))
A12: MVP | B12: BA | C12: =SUMIFS(WBS!F2:F94,WBS!D2:D94,A12,WBS!E2:E94,B12) | D12: =SUMIFS(WBS!G2:G94,WBS!D2:D94,A12,WBS!E2:E94,B12) | E12: =IF(C12=0,"",ROUND(D12/C12,2))
A13: MVP | B13: BrSE | C13: =SUMIFS(WBS!F2:F94,WBS!D2:D94,A13,WBS!E2:E94,B13) | D13: =SUMIFS(WBS!G2:G94,WBS!D2:D94,A13,WBS!E2:E94,B13) | E13: =IF(C13=0,"",ROUND(D13/C13,2))
A14: MVP | B14: AI Engineer | C14: =SUMIFS(WBS!F2:F94,WBS!D2:D94,A14,WBS!E2:E94,B14) | D14: =SUMIFS(WBS!G2:G94,WBS!D2:D94,A14,WBS!E2:E94,B14) | E14: =IF(C14=0,"",ROUND(D14/C14,2))
A15: MVP | B15: Backend | C15: =SUMIFS(WBS!F2:F94,WBS!D2:D94,A15,WBS!E2:E94,B15) | D15: =SUMIFS(WBS!G2:G94,WBS!D2:D94,A15,WBS!E2:E94,B15) | E15: =IF(C15=0,"",ROUND(D15/C15,2))
A16: MVP | B16: Frontend | C16: =SUMIFS(WBS!F2:F94,WBS!D2:D94,A16,WBS!E2:E94,B16) | D16: =SUMIFS(WBS!G2:G94,WBS!D2:D94,A16,WBS!E2:E94,B16) | E16: =IF(C16=0,"",ROUND(D16/C16,2))
A17: MVP | B17: QA | C17: =SUMIFS(WBS!F2:F94,WBS!D2:D94,A17,WBS!E2:E94,B17) | D17: =SUMIFS(WBS!G2:G94,WBS!D2:D94,A17,WBS!E2:E94,B17) | E17: =IF(C17=0,"",ROUND(D17/C17,2))
A18: MVP | B18: Infra | C18: =SUMIFS(WBS!F2:F94,WBS!D2:D94,A18,WBS!E2:E94,B18) | D18: =SUMIFS(WBS!G2:G94,WBS!D2:D94,A18,WBS!E2:E94,B18) | E18: =IF(C18=0,"",ROUND(D18/C18,2))
A19: Tổng MVP | C19: =SUMIFS(WBS!F2:F94,WBS!D2:D94,"MVP") | D19: =SUMIFS(WBS!G2:G94,WBS!D2:D94,"MVP") | E19: =IF(C19=0,"",ROUND(D19/C19,2))
A20: Production | B20: PM | C20: =SUMIFS(WBS!F2:F94,WBS!D2:D94,A20,WBS!E2:E94,B20) | D20: =SUMIFS(WBS!G2:G94,WBS!D2:D94,A20,WBS!E2:E94,B20) | E20: =IF(C20=0,"",ROUND(D20/C20,2))
A21: Production | B21: BA | C21: =SUMIFS(WBS!F2:F94,WBS!D2:D94,A21,WBS!E2:E94,B21) | D21: =SUMIFS(WBS!G2:G94,WBS!D2:D94,A21,WBS!E2:E94,B21) | E21: =IF(C21=0,"",ROUND(D21/C21,2))
A22: Production | B22: BrSE | C22: =SUMIFS(WBS!F2:F94,WBS!D2:D94,A22,WBS!E2:E94,B22) | D22: =SUMIFS(WBS!G2:G94,WBS!D2:D94,A22,WBS!E2:E94,B22) | E22: =IF(C22=0,"",ROUND(D22/C22,2))
A23: Production | B23: AI Engineer | C23: =SUMIFS(WBS!F2:F94,WBS!D2:D94,A23,WBS!E2:E94,B23) | D23: =SUMIFS(WBS!G2:G94,WBS!D2:D94,A23,WBS!E2:E94,B23) | E23: =IF(C23=0,"",ROUND(D23/C23,2))
A24: Production | B24: Backend | C24: =SUMIFS(WBS!F2:F94,WBS!D2:D94,A24,WBS!E2:E94,B24) | D24: =SUMIFS(WBS!G2:G94,WBS!D2:D94,A24,WBS!E2:E94,B24) | E24: =IF(C24=0,"",ROUND(D24/C24,2))
A25: Production | B25: Frontend | C25: =SUMIFS(WBS!F2:F94,WBS!D2:D94,A25,WBS!E2:E94,B25) | D25: =SUMIFS(WBS!G2:G94,WBS!D2:D94,A25,WBS!E2:E94,B25) | E25: =IF(C25=0,"",ROUND(D25/C25,2))
A26: Production | B26: QA | C26: =SUMIFS(WBS!F2:F94,WBS!D2:D94,A26,WBS!E2:E94,B26) | D26: =SUMIFS(WBS!G2:G94,WBS!D2:D94,A26,WBS!E2:E94,B26) | E26: =IF(C26=0,"",ROUND(D26/C26,2))
A27: Production | B27: Infra | C27: =SUMIFS(WBS!F2:F94,WBS!D2:D94,A27,WBS!E2:E94,B27) | D27: =SUMIFS(WBS!G2:G94,WBS!D2:D94,A27,WBS!E2:E94,B27) | E27: =IF(C27=0,"",ROUND(D27/C27,2))
A28: Tổng Production | C28: =SUMIFS(WBS!F2:F94,WBS!D2:D94,"Production") | D28: =SUMIFS(WBS!G2:G94,WBS!D2:D94,"Production") | E28: =IF(C28=0,"",ROUND(D28/C28,2))

Sheet Lịch thực tế
A1: Giai đoạn | B1: Bắt đầu | C1: Kết thúc | D1: Số tuần
A2: PoC | B2: 2025-03-03 | C2: 2025-06-06 | D2: 14
A3: Đánh giá go/no-go, ký hợp đồng | B3: 2025-06-09 | C3: 2025-06-27 | D3: 3
A4: MVP (本開発) | B4: 2025-06-30 | C4: 2025-11-28 | D4: 22
A5: Production (展開・運用) | B5: 2025-12-01 | C5: 2026-02-06 | D5: 10

Sheet Bài học
A1: # | B1: Bài học
A2: 1 | B2: PoC kéo dài từ 10 lên 14 tuần vì OCR chữ viết tay và bảng biểu đạt chất lượng thấp, phải thêm bước người kiểm tra.
A3: 2 | B3: Nên lấy mẫu 50 trang scan ngẫu nhiên đo chất lượng OCR trước khi chốt effort.
